#VRML_SIM R2021a utf8
WorldInfo {
  basicTimeStep 16
  coordinateSystem "NUE"
}
Viewpoint {
  orientation -0.06878400006252043 0.9916019884311058 0.10951829926946544 2.0275828491700043
  position 2.21671208568707 0.8768826340149992 -1.1778062119343704
}
TexturedBackground {
}
TexturedBackgroundLight {
}
RectangleArena {
  floorSize 10 10
  floorTileSize 1 1
  wallHeight 1
}
DEF Rover Robot {
  translation 0 0.5 0
  children [
    DEF Joint_central_derecho HingeJoint {
      jointParameters DEF joint_rocker_der HingeJointParameters {
        axis 0 0 1
        anchor 0 0 -0.33
      }
      device [
        PositionSensor {
          name "der_joint_chasis"
        }
      ]
      endPoint DEF rocker_der Solid {
        translation 0 0 -0.33
        rotation 0 0 1 0
        children [
          DEF directional_der_rocker HingeJoint {
            jointParameters DEF der_rocker_directional HingeJointParameters {
              axis 0 1 0
              anchor -0.52 -0.283 0
            }
            device [
              RotationalMotor {
                name "der_rocker_directional"
                maxTorque 1000000
              }
            ]
            endPoint Solid {
              translation -0.52 -0.293 0
              children [
                DEF rocker_der_wheel HingeJoint {
                  jointParameters HingeJointParameters {
                    axis 0 0 1
                    anchor 0 -0.0673 0.0383
                  }
                  device [
                    RotationalMotor {
                      name "wheel_rocker_der"
                      maxTorque 100
                    }
                  ]
                  endPoint Solid {
                    translation 0 -0.0673187 -0.0383453
                    rotation 1 0 0 1.5708003061004252
                    children [
                      Shape {
                        appearance GenericTireAppearance {
                        }
                        geometry DEF rueda Cylinder {
                          height 0.05
                          radius 0.08
                        }
                      }
                    ]
                    boundingObject USE rueda
                    physics Physics {
                    }
                  }
                }
                DEF rocker_directional_der Shape {
                  appearance BrushedSteel {
                  }
                  geometry Box {
                    size 0.05 0.1 0.05
                  }
                }
              ]
              name "solid(1)"
              boundingObject USE rocker_directional_der
              physics Physics {
              }
            }
          }
          DEF boogie_der HingeJoint {
            jointParameters DEF boogie_der HingeJointParameters {
              axis 0 0 1
              anchor 0.22 -0.133 0
            }
            device [
              DEF boogie_der PositionSensor {
                name "der_joint_boggie"
              }
            ]
            endPoint DEF boogie_left Solid {
              translation 0.22 -0.133 0
              rotation 0 0 1 0
              children [
                DEF middle_wheel_der_boggie HingeJoint {
                  jointParameters HingeJointParameters {
                    axis 0 0 1
                    anchor -0.17 -0.228 -0.0484
                  }
                  device [
                    RotationalMotor {
                      name "middle_wheel_der"
                    }
                  ]
                  endPoint Solid {
                    translation -0.170411 -0.227587 -0.0484
                    rotation 0.9990323316930704 -0.03109989345025776 -0.031099788733837393 1.5717678305469145
                    children [
                      DEF wheel Shape {
                        appearance GenericTireAppearance {
                        }
                        geometry Cylinder {
                          height 0.05
                          radius 0.08
                        }
                      }
                    ]
                    name "solid(1)"
                    boundingObject USE wheel
                    physics Physics {
                    }
                  }
                }
                DEF directional_der_boggie HingeJoint {
                  jointParameters DEF der_boggie_directional HingeJointParameters {
                    axis 0 1 0
                    anchor 0.25 -0.16 0
                  }
                  device [
                    RotationalMotor {
                      name "der_boggie_directional"
                      maxTorque 1000000
                    }
                  ]
                  endPoint Solid {
                    translation 0.25 -0.16 0
                    children [
                      DEF boggie_left_wheel HingeJoint {
                        jointParameters HingeJointParameters {
                          axis 0 0 1
                          anchor 0 -0.0673 0.0517
                        }
                        device [
                          RotationalMotor {
                            name "wheel_boggie_der"
                            maxTorque 100
                          }
                        ]
                        endPoint Solid {
                          translation 0 -0.0673188 -0.0483453
                          rotation 1 0 0 1.5708003061004252
                          children [
                            Shape {
                              appearance GenericTireAppearance {
                              }
                              geometry DEF rueda Cylinder {
                                height 0.05
                                radius 0.08
                              }
                            }
                          ]
                          boundingObject USE rueda
                          physics Physics {
                          }
                        }
                      }
                      DEF boggie_directional_left Shape {
                        appearance BrushedSteel {
                        }
                        geometry Box {
                          size 0.05 0.1 0.05
                        }
                      }
                    ]
                    boundingObject USE boggie_directional_left
                    physics Physics {
                    }
                  }
                }
                DEF Boggie Group {
                  children [
                    Transform {
                      translation -0.17 -0.16 0
                      children [
                        Shape {
                          appearance BrushedSteel {
                          }
                          geometry Box {
                            size 0.05 0.1 0.05
                          }
                        }
                      ]
                    }
                    Transform {
                      translation 0.116767 -0.0652523 0
                      rotation 0 0 1 1.1
                      children [
                        Shape {
                          appearance BrushedAluminium {
                          }
                          geometry Cylinder {
                            height 0.3
                            radius 0.03
                          }
                        }
                      ]
                    }
                    Transform {
                      translation -0.084 -0.061 0
                      rotation 0 0 1 -0.9162996938995747
                      children [
                        Shape {
                          appearance BrushedAluminium {
                          }
                          geometry Cylinder {
                            height 0.25
                            radius 0.03
                          }
                        }
                      ]
                    }
                  ]
                }
              ]
              boundingObject USE Boggie
              physics Physics {
              }
            }
          }
          DEF Rocker-Boogie-left Group {
            children [
              Transform {
                translation 0.11 -0.068 0
                rotation 0 0 1 1.0471996938995747
                children [
                  Shape {
                    appearance BrushedAluminium {
                    }
                    geometry Cylinder {
                      height 0.3
                      radius 0.03
                    }
                  }
                ]
              }
              Transform {
                translation -0.26 -0.13 0
                rotation 0 0 1 -1.1
                children [
                  Shape {
                    appearance BrushedAluminium {
                    }
                    geometry Cylinder {
                      height 0.6
                      radius 0.03
                    }
                  }
                ]
              }
            ]
          }
        ]
        boundingObject USE Rocker-Boogie-left
        physics Physics {
        }
      }
    }
    DEF Joint_central_izquierdo HingeJoint {
      jointParameters DEF joint_rocker_izq HingeJointParameters {
        axis 0 0 1
        anchor 0 0 0.33
      }
      device [
        PositionSensor {
          name "left_joint_chasis"
        }
      ]
      endPoint DEF rocker_izq Solid {
        translation 0 0 0.33
        rotation 0 0 1 0
        children [
          DEF directional_left_rocker HingeJoint {
            jointParameters DEF left_rocker_directional HingeJointParameters {
              axis 0 1 0
              anchor -0.52 -0.283 0
            }
            device [
              RotationalMotor {
                name "left_rocker_directional"
                maxTorque 1000000
              }
            ]
            endPoint Solid {
              translation -0.52 -0.293 0
              children [
                DEF rocker_left_wheel HingeJoint {
                  jointParameters HingeJointParameters {
                    axis 0 0 1
                    anchor 0 -0.0673 0.0517
                  }
                  device [
                    RotationalMotor {
                      name "wheel_rocker_left"
                      maxTorque 100
                    }
                  ]
                  endPoint Solid {
                    translation 0 -0.0673188 0.0516547
                    rotation 1 0 0 1.5708003061004252
                    children [
                      Shape {
                        appearance GenericTireAppearance {
                        }
                        geometry DEF rueda Cylinder {
                          height 0.05
                          radius 0.08
                        }
                      }
                    ]
                    boundingObject USE rueda
                    physics Physics {
                    }
                  }
                }
                DEF rocker_directional_left Shape {
                  appearance BrushedSteel {
                  }
                  geometry Box {
                    size 0.05 0.1 0.05
                  }
                }
              ]
              boundingObject USE rocker_directional_left
              physics Physics {
              }
            }
          }
          DEF boogie_left HingeJoint {
            jointParameters DEF boogie_left HingeJointParameters {
              axis 0 0 1
              anchor 0.22 -0.133 0.33
            }
            device [
              DEF boogie_left PositionSensor {
                name "left_joint_boggie"
              }
            ]
            endPoint DEF boogie_left Solid {
              translation 0.22 -0.133 0
              rotation 0 0 1 0
              children [
                DEF middle_wheel_left_boggie HingeJoint {
                  jointParameters HingeJointParameters {
                    axis 0 0 1
                    anchor -0.17 -0.228 0.0516
                  }
                  device [
                    RotationalMotor {
                      name "middle_wheel_left"
                    }
                  ]
                  endPoint Solid {
                    translation -0.17041051839981805 -0.2275872205552426 0.05160000000000002
                    rotation 0.9990323316930704 -0.03109989345025776 -0.031099788733837393 1.5717678305469145
                    children [
                      DEF wheel Shape {
                        appearance GenericTireAppearance {
                        }
                        geometry Cylinder {
                          height 0.05
                          radius 0.08
                        }
                      }
                    ]
                    boundingObject USE wheel
                    physics Physics {
                    }
                  }
                }
                DEF directional_left_boggie HingeJoint {
                  jointParameters DEF left_boggie_directional HingeJointParameters {
                    axis 0 1 0
                    anchor 0.25 -0.16 0
                  }
                  device [
                    RotationalMotor {
                      name "left_boggie_directional"
                      maxTorque 1000000
                    }
                  ]
                  endPoint Solid {
                    translation 0.25 -0.16 0
                    children [
                      DEF boggie_left_wheel HingeJoint {
                        jointParameters HingeJointParameters {
                          axis 0 0 1
                          anchor 0 -0.0673 0.0517
                        }
                        device [
                          RotationalMotor {
                            name "wheel_boggie_left"
                            maxTorque 100
                          }
                        ]
                        endPoint Solid {
                          translation 0 -0.0673188 0.0516547
                          rotation 1 0 0 1.5708003061004252
                          children [
                            Shape {
                              appearance GenericTireAppearance {
                              }
                              geometry DEF rueda Cylinder {
                                height 0.05
                                radius 0.08
                              }
                            }
                          ]
                          boundingObject USE rueda
                          physics Physics {
                          }
                        }
                      }
                      DEF boggie_directional_left Shape {
                        appearance BrushedSteel {
                        }
                        geometry Box {
                          size 0.05 0.1 0.05
                        }
                      }
                    ]
                    boundingObject USE boggie_directional_left
                    physics Physics {
                    }
                  }
                }
                DEF Boggie Group {
                  children [
                    Transform {
                      translation -0.17 -0.16 0
                      children [
                        Shape {
                          appearance BrushedSteel {
                          }
                          geometry Box {
                            size 0.05 0.1 0.05
                          }
                        }
                      ]
                    }
                    Transform {
                      translation 0.116767 -0.0652523 0
                      rotation 0 0 1 1.1
                      children [
                        Shape {
                          appearance BrushedAluminium {
                          }
                          geometry Cylinder {
                            height 0.3
                            radius 0.03
                          }
                        }
                      ]
                    }
                    Transform {
                      translation -0.084 -0.061 0
                      rotation 0 0 1 -0.9162996938995747
                      children [
                        Shape {
                          appearance BrushedAluminium {
                          }
                          geometry Cylinder {
                            height 0.25
                            radius 0.03
                          }
                        }
                      ]
                    }
                  ]
                }
              ]
              boundingObject USE Boggie
              physics Physics {
              }
            }
          }
          DEF Rocker-Boogie-left Group {
            children [
              Transform {
                translation 0.11 -0.068 0
                rotation 0 0 1 1.0471996938995747
                children [
                  Shape {
                    appearance BrushedAluminium {
                    }
                    geometry Cylinder {
                      height 0.3
                      radius 0.03
                    }
                  }
                ]
              }
              Transform {
                translation -0.26 -0.13 0
                rotation 0 0 1 -1.1
                children [
                  Shape {
                    appearance BrushedAluminium {
                    }
                    geometry Cylinder {
                      height 0.6
                      radius 0.03
                    }
                  }
                ]
              }
            ]
          }
        ]
        boundingObject USE Rocker-Boogie-left
        physics Physics {
        }
      }
    }
    DEF Chasis Shape {
      appearance PBRAppearance {
        baseColor 0.5 0.5 0.5
        metalness 0.5
      }
      geometry DEF Chasis Box {
        size 0.8 0.2 0.6
      }
    }
  ]
  boundingObject USE Chasis
  physics Physics {
  }
  controller "Coltrol_prueba_movimiento"
}
